Workbook

Sheet Performance
C1: Project: | D1: Same Table / 糖友同枱 - shared home dinner planning for diabetes patients (Hospital Authority, classroom prototype)
D2: There are three pipelines in this app.
D3: Pipeline 1 (understand the cook's request) is highly relevant to the project objective and therefore, it requires finetuning.
D4: Pipeline 2 (retrieve dishes from the labeled library) does not require finetuning.
D5: Pipeline 3 (turn a Cantonese voice note into the request text) does not require finetuning.
C6: Experiment: Selecting the optimal model(s) | J6: Experiment: Assessing the overall performance
C8: Step 1: Select THREE relevant and comparable pre-trained models | E8: Step 2a: Finetune the selected models with own dataset | J8: Step 3: Implement the App and deploy it to Streamlit Cloud
C9: Pipeline 1 - Multi-label text classification (to be finetuned) | E9: Fine-tuning | J9: 1. Deployment
E10: Dataset: | F10: data/train/p1_train.jsonl, p1_eval.jsonl, p1_test.jsonl | K10: App = pipeline 1 (finetuned hfl/chinese-roberta-wwm-ext) + pipeline 2 (BAAI/bge-small-zh-v1.5, hybrid weight 3) + plating rules
E11: training samples: | F11: 3000 | K11: Pipeline 1 as deployed (finetuned model + keyword lexicon), accuracy on the hand-written sentences: 0.852
E12: evaluation samples: | F12: 600
E13: testing samples (hand-written): | F13: =COUNTA('P1 test'!A2:A109) | J13: 2. Test and evaluate the App (20 test samples) | M13: Objective judgement: tags, dish count, no repeats, methods, soup, 20-min, balance
J14: Test | K14: Inputs (people | request | chips) | L14: Outputs (tags found | menu) | M14: Correct or not (notebook) | N14: Checked on Streamlit Cloud (fill in: Correct / Incorrect)
D15: Model name | E15: Accuracy (after finetuning, using trainer.evaluate()) | F15: Run time (in sec. per 100 requests, CPU) | G15: Fine-tuning time (in sec.) | H15: Accuracy on hand-written test | J15: Test sample 1 | K15: 4 people | 阿爸牙唔好，想食啲軟熟嘅蒸餸，唔好太甜 | L15: tags: less_sweet, steam | 不會失敗的蒸蛋 / 清蒸山藥｜三鮮肉丸 / 蝦仁蒸蛋豆腐 / 甜豌豆炒菇 / 蒜炒小白菜/快炒/5分鐘/簡單快速 / 客家鹹湯圓的“炒料” | M15: Correct
C16: Model 1 | D16: hfl/rbt3 | E16: 0.595 | F16: 2.97 | G16: 16.6 | H16: 0.8148 | J16: Test sample 2 | K16: 2 people | 今晚好趕，求其炒兩個餸就算 | L16: tags: quick, stir | 好市多牛三寶炒蒜苗 / 菠菜炒鴻禧菇 / 蒜炒小白菜/快炒/5分鐘/簡單快速 | M16: Correct
C17: Model 2 | D17: hfl/rbt6 | E17: 0.6033 | F17: 5.44 | G17: 27.6 | H17: 0.8611 | J17: Test sample 3 | K17: 6 people | 想煲湯，另外加個白灼菜 | L17: tags: blanch, soup | 白切雞 / 『涼拌皮蛋』－清爽、酸辣、開胃。 / 涼拌魚皮 / 芹菜炒花枝 / 家常小菜-涼拌干絲 / 《料理簡單做》涼拌萵筍/菜心 / 涼拌萵筍 ( A菜心 ) / 客家鹹湯圓的“炒料” | M17: Correct
C18: Model 3 | D18: hfl/chinese-roberta-wwm-ext | E18: 0.6667 | F18: 10.78 | G18: 54.2 | H18: =COUNTIF('P1 test'!D2:D109,"Correct")/COUNTA('P1 test'!D2:D109) | J18: Test sample 4 | K18: 5 people | 屋企有三個男仔，肉要多 | L18: tags: more_meat | 好市多牛三寶炒蒜苗 / 十三香炒回鍋肉 / 青椒炒肉絲 - 家常料理 / 菠菜炒鴻禧菇 / 免炒無油無糖自製棗泥 / 素食版的粄條😋 蔬炒粄條🤤 / 薑絲石斑魚蛤蜊湯 | M18: Correct
C19: Baseline | D19: keyword lexicon (no model, no training) | E19: 0.3983 | F19: 0.012 | G19: 0 | H19: 0.6481 | J19: Test sample 5 | K19: 3 people | 最近食得好油，想清清地 | L19: tags: more_veg | 『涼拌皮蛋』－清爽、酸辣、開胃。 / 清炒小黃瓜 / 蒜炒菜心 / 山藥排骨湯 | M19: Correct
C20: Baseline | D20: MoritzLaurer/mDeBERTa-v3-base-mnli-xnli (zero-shot, no training) | E20: n/a | F20: 2371.15 | G20: 0 | H20: 0.287 | J20: Test sample 6 | K20: 4 people | (empty box) [chips: steam, soup] | L20: tags: soup, steam | 不會失敗的蒸蛋 / 清蒸山藥｜三鮮肉丸 / 清蒸石斑魚 / 百合蒸东星斑 / 炒結頭菜乾 / 🍲懶人火鍋_康寶極湯味日式高湯包 | M20: Correct
D21: Accuracy = all 8 tags of a sentence correct (exact match). Settings: 3 epochs, learning rate 5e-05, batch 16, fine-tuned on cuda. Source: notebooks/Model1_finetune_tagger.ipynb. The picked model's hand-written accuracy is a formula over sheet 'P1 test'. | J21: Test sample 7 | K21: 4 people | (empty box) | L21: tags: (none) | 青椒炒肉絲 - 家常料理 / 好市多牛三寶炒蒜苗 / 蒜香鮮蝦炒彩蔬 / 家常小菜-涼拌干絲 / 《料理簡單做》涼拌萵筍/菜心 / 客家鹹湯圓的“炒料” | M21: Correct
J22: Test sample 8 | K22: 1 people | 七點先放工，要十五分鐘搞得掂 | L22: tags: quick | 十三香炒回鍋肉 / 蒜炒小白菜/快炒/5分鐘/簡單快速 | M22: Correct
E23: Step 2b: Pick the BEST finetuned model for implementation | J23: Test sample 9 | K23: 6 people | 婆婆糖尿，醬汁唔可以甜 [chips: more_veg] | L23: tags: less_sweet, more_veg | 好市多牛三寶炒蒜苗 / 炒櫻桃鴨胸 / 蝦仁炒毛豆 / 甜豌豆炒菇 / 涼拌櫛瓜 / 蒜炒菜心 / 薑絲高麗菜炒小黃瓜 / 白菜蛋花湯 | M23: Correct
E24: hfl/chinese-roberta-wwm-ext is picked: highest evaluation accuracy; models within one standard error of the best are tied and the shortest run time wins. | J24: Test sample 10 | K24: 3 people | 今晚想吃清蒸的，配一個燙青菜 | L24: tags: blanch, steam | 清蒸山藥｜三鮮肉丸 / 清蒸石斑魚 / 家常小菜-涼拌干絲 / 榭黃芥菜羹｜立春節氣料理 | M24: Correct
E25: The finetuned model is uploaded to Hugging Face as Tannedfish95/same-table-tagger and is used for implementing the App. | J25: Test sample 11 | K25: 4 people | quick stir fry with lots of veggies | L25: tags: more_veg, quick, stir | 爆香麻辣雞肝 / 芹菜炒花枝 / 薑絲高麗菜炒小黃瓜 / 芹菜小黃瓜炒豆腐 / 清炒小芥菜 / 酸菜豬血湯 | M25: Correct
J26: Test sample 12 | K26: 5 people | we want more meat tonight and a soup | L26: tags: more_veg, soup | 涼拌小黃瓜雞絲 / 芥藍菜炒鹹豬肉 / 蒜蓉蒸蝦 / 小黃瓜炒杏鮑菇及火腿片 / 清炒小芥菜 / 鹽炒花生 / 酸菜豬血湯 | M26: Incorrect (tags)
J27: Test sample 13 | K27: 2 people | 落雨天想飲啖熱湯 | L27: tags: soup | 豬肉辣炒高麗菜乾 / 涼拌萵筍 ( A菜心 ) / 🍲懶人火鍋_康寶極湯味日式高湯包 | M27: Correct
C28: Step 1: Select THREE relevant and comparable pre-trained models | E28: Step 2a: Test the performance of the selected models with your own dataset | J28: Test sample 14 | K28: 4 people | 想食得有鑊氣，炒牛肉都好 | L28: tags: stir | 好市多牛三寶炒蒜苗 / 香菇肉末炒龍鬚菜 / 洋蔥毛肚炒蒜苗 / 清炒小黃瓜 / 芹菜鮮蔬炒豆乾 / 清燉牛肉湯 | M28: Correct
C29: Pipeline 2 - Feature extraction (sentence embeddings for dish retrieval, not finetuned) | J29: Test sample 15 | K29: 6 people | 蒸魚，炒菜，再加個湯 | L29: tags: soup, steam, stir | 不會失敗的蒸蛋 / 清蒸山藥｜三鮮肉丸 / 懶人蒸爐料理-鳳梨醬蒸魚 / 清蒸石斑魚 / 蒜炒小白菜/快炒/5分鐘/簡單快速 / 百合蒸东星斑 / 炒結頭菜乾 / 客家鹹湯圓的“炒料” | M29: Correct
E30: Dataset: | F30: data/train/p2_dev.jsonl (development), p2_test.jsonl + p2_paraphrase_test.jsonl (testing) | J30: Test sample 16 | K30: 3 people | 十五分鐘煮好，灼個菜蒸條魚 | L30: tags: blanch, quick, steam | 不會失敗的蒸蛋 / 懶人蒸爐料理-鳳梨醬蒸魚 / 蒜炒小白菜/快炒/5分鐘/簡單快速 / 薑絲石斑魚蛤蜊湯 | M30: Incorrect (methods on menu)
E31: development samples (set the hybrid weight): | F31: 600 | J31: Test sample 17 | K31: 4 people | 多菜少肉，唔好甜 [chips: quick] | L31: tags: less_sweet, more_veg, quick | 好市多牛三寶炒蒜苗 / 蝦仁炒毛豆 / 甜豌豆炒菇 / 薑絲高麗菜炒小黃瓜 / 蒜炒小白菜/快炒/5分鐘/簡單快速 / 鹹菜蒜頭蛤蠣雞湯（電鍋/一鍋到底） | M31: Correct
E32: testing samples (literal queries): | F32: =COUNTA('P2 queries'!A2:A201) | J32: Test sample 18 | K32: 2 people | 隨便啦 [chips: blanch] | L32: tags: blanch | 白切雞 / 涼拌魚皮 / 家常小菜-涼拌干絲 | M32: Correct
E33: testing samples (paraphrase queries): | F33: 24 | J33: Test sample 19 | K33: 5 people | 長輩血糖高，不要甜的 | L33: tags: less_sweet | 豬肉辣炒高麗菜乾 / 洋蔥炒鹹豬肉 / 蝦仁炒毛豆 / 古早味鯖魚罐頭炒高麗菜 / 甜豌豆炒菇 / 免炒無油無糖自製棗泥 / 酸菜豬血湯 | M33: Correct
E34: library dishes searched: | F34: 100 | J34: Test sample 20 | K34: 4 people | 雪櫃有雞胸同菠菜 | L34: tags: (none) | 涼拌小黃瓜雞絲 / 炒櫻桃鴨胸 / 菠菜炒鴻禧菇 / 小黃瓜炒杏鮑菇 / 小黃瓜炒杏鮑菇及火腿片 / 鹹菜蒜頭蛤蠣雞湯（電鍋/一鍋到底） | M34: Correct
D36: Model name | E36: Performance (top-5 accuracy, literal queries) | F36: Run time (in sec. per 100 queries, CPU) | G36: Top-1 accuracy | H36: Paraphrase precision@5 | I36: Hybrid weight w | L36: Accuracy (notebook): | M36: =COUNTIF(M15:M34,"Correct")&" out of "&COUNTA(M15:M34)
C37: Model 1 | D37: BAAI/bge-small-zh-v1.5 | E37: =COUNTIF('P2 queries'!D2:D201,"<=5")/COUNT('P2 queries'!D2:D201) | F37: 0.98 | G37: =COUNTIF('P2 queries'!D2:D201,1)/COUNT('P2 queries'!D2:D201) | H37: 0.5417 | I37: 3 | M37: =COUNTIF(M15:M34,"Correct")/COUNTA(M15:M34)
C38: Model 2 | D38: shibing624/text2vec-base-chinese | E38: =COUNTIF('P2 queries'!E2:E201,"<=5")/COUNT('P2 queries'!E2:E201) | F38: 2.34 | G38: =COUNTIF('P2 queries'!E2:E201,1)/COUNT('P2 queries'!E2:E201) | H38: 0.5833 | I38: 2 | L38: Accuracy (Streamlit Cloud): | N38: =IF(COUNTA(N15:N34)=0,"not checked yet",COUNTIF(N15:N34,"Correct")/COUNTA(N15:N34))
C39: Model 3 | D39: sentence-transformers/paraphrase-multilingual-MiniLM-L12-v2 | E39: =COUNTIF('P2 queries'!F2:F201,"<=5")/COUNT('P2 queries'!F2:F201) | F39: 1.04 | G39: =COUNTIF('P2 queries'!F2:F201,1)/COUNT('P2 queries'!F2:F201) | H39: 0.6 | I39: 5
C40: Baseline | D40: character TF-IDF (no model) | E40: =COUNTIF('P2 queries'!C2:C201,"<=5")/COUNT('P2 queries'!C2:C201) | F40: 0.24 | G40: =COUNTIF('P2 queries'!C2:C201,1)/COUNT('P2 queries'!C2:C201) | H40: 0.475 | L40: Legend: fill the shaded column N after repeating each request on the deployed app (type Correct or Incorrect). Green rows = picked models.
D41: A query is correct when its target dish is ranked in the top 5 of the library (the menu shows 6-8 dishes). Each encoder runs through the app's Retriever: score = cosine similarity + w x character TF-IDF, with w set on the development queries only. Source: notebooks/Model2_experiments.ipynb; accuracy cells are formulas over sheet 'P2 queries'.
E43: Step 2b: Pick the BEST model for implementation | J43: 3. Voice-note tests on Streamlit Cloud (pipeline 3: alvanlii/whisper-small-cantonese)
...

Sheet P1 test
A1: Hand-written test sentence | B1: Expected tags | C1: Predicted tags (hfl/chinese-roberta-wwm-ext, fine-tuned) | D1: Correct or not
A2: 阿爸牙唔好，想食啲軟熟嘅蒸餸，唔好太甜 | B2: steam, less_sweet | C2: steam, less_sweet | D2: =IF(B2=C2,"Correct","Incorrect")
A3: 今晚好趕，求其炒兩個餸就算 | B3: stir, quick | C3: stir, quick | D3: =IF(B3=C3,"Correct","Incorrect")
A4: 想煲湯，另外加個白灼菜 | B4: blanch, soup | C4: blanch, soup | D4: =IF(B4=C4,"Correct","Incorrect")
A5: 屋企有三個男仔，肉要多 | B5: more_meat | C5: more_meat | D5: =IF(B5=C5,"Correct","Incorrect")
A6: 最近食得好油，想清清地 | B6: more_veg | C6: more_veg | D6: =IF(B6=C6,"Correct","Incorrect")
A7: 可唔可以蒸魚加個湯 | B7: steam, soup | C7: steam, soup | D7: =IF(B7=C7,"Correct","Incorrect")
A8: 七點先放工，要十五分鐘搞得掂 | B8: quick | C8: quick | D8: =IF(B8=C8,"Correct","Incorrect")
A9: 婆婆糖尿，醬汁唔可以甜 | B9: less_sweet | C9: less_sweet | D9: =IF(B9=C9,"Correct","Incorrect")
A10: 今晚想吃清蒸的，配一個燙青菜 | B10: steam, blanch | C10: steam, blanch | D10: =IF(B10=C10,"Correct","Incorrect")
A11: 我想喝湯，還要一個快炒 | B11: soup, stir | C11: soup, stir | D11: =IF(B11=C11,"Correct","Incorrect")
A12: something steamed and not sweet | B12: steam, less_sweet | C12: steam, less_sweet | D12: =IF(B12=C12,"Correct","Incorrect")
A13: quick stir fry with lots of veggies | B13: stir, more_veg, quick | C13: stir, more_veg, quick | D13: =IF(B13=C13,"Correct","Incorrect")
... A109: 湯水唔好甜 | B109: soup, less_sweet | C109: soup, less_sweet | D109: =IF(B109=C109,"Correct","Incorrect")

Sheet P2 queries
A1: Query | B1: Target dish | C1: Rank of target: character TF-IDF (no model) | D1: Rank of target: BAAI/bge-small-zh-v1.5 | E1: Rank of target: shibing624/text2vec-base-chinese | F1: Rank of target: sentence-transformers/paraphrase-multilingual-MiniLM-L12-v2
A2: 青椒鹹豬肉可以點整 | B2: 青椒炒鹹豬肉 | C2: 1 | D2: 1 | E2: 1 | F2: 1
A3: 想要一道炒嘅肉，材料有鹹豬肉 | B3: 青椒炒鹹豬肉 | C3: 2 | D3: 2 | E3: 3 | F3: 2
A4: 街市買到靚紅蘿蔔，想快炒 | B4: 紅蘿蔔馬鈴薯炒雞軟骨 | C4: 3 | D4: 3 | E4: 4 | F4: 3
A5: 想要一道炒嘅肉類，材料有醃製雞軟骨 | B5: 紅蘿蔔馬鈴薯炒雞軟骨 | C5: 1 | D5: 1 | E5: 1 | F5: 1
A6: 辣椒青椒可以點整 | B6: 炒櫻桃鴨胸 | C6: 6 | D6: 8 | E6: 8 | F6: 9
A7: 想要一道快炒嘅肉類，材料有櫻桃鴨胸 | B7: 炒櫻桃鴨胸 | C7: 1 | D7: 1 | E7: 1 | F7: 1
A8: 街市買到靚水煮五花肉，想炒 | B8: 十三香炒回鍋肉 | C8: 1 | D8: 1 | E8: 1 | F8: 1
A9: 想要一道小炒嘅肉，材料有鮮豆包 | B9: 十三香炒回鍋肉 | C9: 2 | D9: 2 | E9: 1 | F9: 2
A10: 德國豬腳蒜苗可以點整 | B10: 德國豬腳香炒大蒜 | C10: 1 | D10: 1 | E10: 1 | F10: 1
A11: 想要一道快炒嘅肉，材料有德國豬腳 | B11: 德國豬腳香炒大蒜 | C11: 1 | D11: 1 | E11: 1 | F11: 1
A12: 雪櫃得返紅葱頭，點算 | B12: (韓式)辣炒排骨 🌶️🌶️🌶️ | C12: 1 | D12: 1 | E12: 1 | F12: 1
A13: 紅葱末排骨可以點整 | B13: (韓式)辣炒排骨 🌶️🌶️🌶️ | C13: 1 | D13: 1 | E13: 1 | F13: 2
... A201: 想要一道湯嘅湯，材料有蒜苗 | B201: 客家鹹湯圓的“炒料” | C201: 1 | D201: 1 | E201: 1 | F201: 1

Sheet P3 clips
A1: Clip (data/speech/) | B1: Reference transcript (Common Voice) | C1: Reference characters | D1: Heard: alvanlii/whisper-small-cantonese | E1: Character errors: alvanlii/whisper-small-cantonese | F1: Heard: safecantonese/whisper-base-yue-hk-mdccl | G1: Character errors: safecantonese/whisper-base-yue-hk-mdccl | H1: Heard: scottykwok/wav2vec2-large-xlsr-cantonese | I1: Character errors: scottykwok/wav2vec2-large-xlsr-cantonese
A2: clips/62688a856cdac0a9.flac | B2: 相思歸去日已暮 | C2: 7 | D2: 相思歸去日已冇 | E2: 1 | F2: 將使閨去日以後 | G2: 5 | H2: 相先歸去日意舞 | I2: 3
A3: clips/5fe7bfedd9ff3351.flac | B3: 任何人，無論你尋日幾風光，今日都可能身敗名裂 | C3: 20 | D3: 任何人，無論你尋日幾光光，今日都可能心敗名裂 | E3: 2 | F3: 任何人無論你尋日幾寬瓜今日都可能心拜明列 | G3: 6 | H3: 任何人無論你尋一幾方光今日都果論心拜明列 | I3: 8
A4: clips/213eb1994cbab4d2.flac | B4: 然後搞到自己一身蟻 | C4: 9 | D4: 然後搞到自己一身蟻 | E4: 0 | F4: 然後搞到自己一身藝 | G4: 1 | H4: 然後攪到自己一新蟻 | I4: 2
A5: clips/4181e5dd5b12a14c.flac | B5: 阿拉伯人好靚啊 | C5: 7 | D5: 阿拉伯人好靚呀 | E5: 1 | F5: 阿拉伯人好靚呀 | G5: 1 | H5: 阿拉白人好靚呀 | I5: 2
A6: clips/5130e2c5cb2fbde2.flac | B6: 依家出街唔使睇綠碼 | C6: 9 | D6: 而家出街唔使睇鹿馬 | E6: 3 | F6: 而家出街唔使睇錄碼 | G6: 2 | H6: 而家出街唔洗體陸馬 | I6: 5
A7: clips/85cf45808a456ad1.flac | B7: 可唔可以幫我解決下問題啊 | C7: 12 | D7: 我唔可以夢和解決下問題呀 | E7: 4 | F7: 我唔可以夢過界嘅堪文題呀 | G7: 8 | H7: 可唔可以幫和街嘅吓文題呀 | I7: 6
A8: clips/dc0e458318e0fc3d.flac | B8: 呢個拼音掛畫仲差美工 | C8: 10 | D8: 呢個拼音怪話仲差美功 | E8: 3 | F8: 呢個拼音掛畫仲差未公 | G8: 2 | H8: 呢個平飲過話仲撐美工 | I8: 5
A9: clips/50d5196fe4db6aca.flac | B9: 我哋幾鬼威啊女 | C9: 7 | D9: 我哋幾鬼威呀女 | E9: 1 | F9: 我哋幾櫃威呀女 | G9: 2 | H9: 我地己鬼威阿女 | I9: 3
A10: clips/945dd426a17ba0cf.flac | B10: 我估佢嘅意思係噉 | C10: 8 | D10: 我估佢嘅意思係噉 | E10: 0 | F10: 我估佢嘅意思係噉 | G10: 0 | H10: 我估佢嘅意思係咁 | I10: 1
A11: clips/b28b5db477523d0d.flac | B11: 唔係，起碼七八十年代之前冇 | C11: 12 | D11: 唔係，起碼七八十年代之前冇 | E11: 0 | F11: 唔係，起碼七八十年代之前好 | G11: 1 | H11: 唔係起馬七八十年代支前母 | I11: 3
A12: clips/6c04d2d04f8bad8c.flac | B12: 好多人都叫潮州 | C12: 7 | D12: 好多人都叫潮州 | E12: 0 | F12: 我多人都叫朝州 | G12: 2 | H12: 好多人都叫潮走 | I12: 1
A13: clips/6d184896851f5023.flac | B13: 你係點認識到佢，佢又有咩吸引你呢 | C13: 15 | D13: 你係點認識到佢，佢又有咩吸引你呢？ | E13: 0 | F13: 你係點認識到佢，佢又有咩吸引你呢？ | G13: 0 | H13: 你係點認識到佢佢又又咩吸緊你呢 | I13: 2
... A201: clips/7f48c0aec7d8d215.flac | B201: 得你一個人搬係冇用 | C201: 9 | D201: 得你一個人半係冇用 | E201: 1 | F201: 得你一個人搬係冇用 | G201: 0 | H201: 得你一個人本係無用 | I201: 2
